<?xml version="1.0" ?>
<!-- =================================================================================== -->
<!-- |    This document was autogenerated by xacro from /home/gurovaid/ims_lab_ws/test_ws/src/xarm_description/urdf/dual_xarm7_robot.urdf.xacro | -->
<!-- |    EDITING THIS FILE BY HAND IS NOT RECOMMENDED                                 | -->
<!-- =================================================================================== -->
<robot name="xarm7">
    <!-- ground instead of world, for the arms to attach -->
    <link name="ground" />
    <!--
  Author: Jimy Zhang <jimy.zhang@ufactory.cc> <jimy92@163.com>
  Contributers:
-->
    <gazebo>
        <plugin filename="libgazebo_ros_control.so" name="gazebo_ros_control">
            <robotNamespace>/xarm</robotNamespace>
            <!-- <controlPeriod>0.0001</controlPeriod> -->
            <robotSimType>gazebo_ros_control/DefaultRobotHWSim</robotSimType>
            <legacyModeNS>true</legacyModeNS>
            <!-- <preserveWorldVelocity>true</preserveWorldVelocity> -->
        </plugin>
    </gazebo>
    <joint name="L_world_joint" type="fixed">
        <parent link="ground" />
        <child link="L_link_base" />
        <origin rpy="0 0 0" xyz="0 0 0" />
    </joint>
    <material name="L_Black">
        <color rgba="0.0 0.0 0.0 1.0" />
    </material>
    <material name="L_Red">
        <color rgba="0.8 0.0 0.0 1.0" />
    </material>
    <material name="L_White">
        <color rgba="1.0 1.0 1.0 1.0" />
    </material>
    <material name="L_Silver">
        <color rgba="0.753 0.753 0.753 1.0" />
    </material>
    <link name="L_link_base">
        <inertial>
            <origin rpy="0 0 0" xyz="-0.021131 -0.0016302 0.056488" />
            <mass value="0.88556" />
            <inertia ixx="0.0030595" ixy="0.00012259" ixz="-0.00062705" iyy="0.0037783" iyz="0.00027023" izz="0.0020125" />
        </inertial>
        <visual>
            <origin rpy="0 0 0" xyz="0 0 0" />
            <geometry>
                <mesh filename="package://xarm_description/meshes/xarm7/visual/link_base.STL" />
            </geometry>
            <material name="L_White" />
        </visual>
        <collision>
            <origin rpy="0 0 0" xyz="0 0 0" />
            <geometry>
                <mesh filename="package://xarm_description/meshes/xarm7/visual/link_base.STL" />
            </geometry>
        </collision>
    </link>
    <link name="L_link1">
        <inertial>
            <origin rpy="0 0 0" xyz="-0.0042142 0.02821 -0.0087788" />
            <mass value="0.42603" />
            <inertia ixx="0.0014243" ixy="3.9946E-05" ixz="4.7078E-06" iyy="0.00123" iyz="-0.00026073" izz="0.00099229" />
        </inertial>
        <visual>
            <origin rpy="0 0 0" xyz="0 0 0" />
            <geometry>
                <mesh filename="package://xarm_description/meshes/xarm7/visual/link1.STL" />
            </geometry>
            <material name="L_White" />
        </visual>
        <collision>
            <origin rpy="0 0 0" xyz="0 0 0" />
            <geometry>
                <mesh filename="package://xarm_description/meshes/xarm7/visual/link1.STL" />
            </geometry>
        </collision>
    </link>
    <joint name="L_joint1" type="revolute">
        <origin rpy="0 0 0" xyz="0 0 0.267" />
        <parent link="L_link_base" />
        <child link="L_link1" />
        <axis xyz="0 0 1" />
        <limit effort="50" lower="-6.283185307179586" upper="6.283185307179586" velocity="3.14" />
        <dynamics damping="10" friction="1" />
    </joint>
    <link name="L_link2">
        <inertial>
            <origin rpy="0 0 0" xyz="-3.3178E-05 -0.12849 0.026337" />
            <mass value="0.56095" />
            <inertia ixx="0.0031915" ixy="3.0892E-06" ixz="2.8729E-06" iyy="0.0017468" iyz="-0.0010241" izz="0.00235" />
        </inertial>
        <visual>
            <origin rpy="0 0 0" xyz="0 0 0" />
            <geometry>
                <mesh filename="package://xarm_description/meshes/xarm7/visual/link2.STL" />
            </geometry>
            <material name="L_White" />
        </visual>
        <collision>
            <origin rpy="0 0 0" xyz="0 0 0" />
            <geometry>
                <mesh filename="package://xarm_description/meshes/xarm7/visual/link2.STL" />
            </geometry>
        </collision>
    </link>
    <joint name="L_joint2" type="revolute">
        <origin rpy="-1.5708 0 0" xyz="0 0 0" />
        <parent link="L_link1" />
        <child link="L_link2" />
        <axis xyz="0 0 1" />
        <limit effort="50" lower="-2.059" upper="2.0944" velocity="3.14" />
        <dynamics damping="10" friction="1" />
    </joint>
    <link name="L_link3">
        <inertial>
            <origin rpy="0 0 0" xyz="0.04223 -0.023258 -0.0096674" />
            <mass value="0.44463" />
            <inertia ixx="0.0011454" ixy="0.0001654" ixz="-0.0001951" iyy="0.0010503" iyz="0.00012027" izz="0.0011083" />
        </inertial>
        <visual>
            <origin rpy="0 0 0" xyz="0 0 0" />
            <geometry>
                <mesh filename="package://xarm_description/meshes/xarm7/visual/link3.STL" />
            </geometry>
            <material name="L_White" />
        </visual>
        <collision>
            <origin rpy="0 0 0" xyz="0 0 0" />
            <geometry>
                <mesh filename="package://xarm_description/meshes/xarm7/visual/link3.STL" />
            </geometry>
        </collision>
    </link>
    <joint name="L_joint3" type="revolute">
        <origin rpy="1.5708 0 0" xyz="0 -0.293 0" />
        <parent link="L_link2" />
        <child link="L_link3" />
        <axis xyz="0 0 1" />
        <limit effort="30" lower="-6.283185307179586" upper="6.283185307179586" velocity="3.14" />
        <dynamics damping="5" friction="1" />
    </joint>
    <link name="L_link4">
        <inertial>
            <origin rpy="0 0 0" xyz="0.067148 -0.10732 0.024479" />
            <mass value="0.52387" />
            <inertia ixx="0.0026033" ixy="0.00053379" ixz="0.00036314" iyy="0.0017649" iyz="-0.00083253" izz="0.0022431" />
        </inertial>
        <visual>
            <origin rpy="0 0 0" xyz="0 0 0" />
            <geometry>
                <mesh filename="package://xarm_description/meshes/xarm7/visual/link4.STL" />
            </geometry>
            <material name="L_White" />
        </visual>
        <collision>
            <origin rpy="0 0 0" xyz="0 0 0" />
            <geometry>
                <mesh filename="package://xarm_description/meshes/xarm7/visual/link4.STL" />
            </geometry>
        </collision>
    </link>
    <joint name="L_joint4" type="revolute">
        <origin rpy="1.5708 0 0" xyz="0.0525 0 0" />
        <parent link="L_link3" />
        <child link="L_link4" />
        <axis xyz="0 0 1" />
        <limit effort="30" lower="-0.19198" upper="3.927" velocity="3.14" />
        <dynamics damping="5" friction="1" />
    </joint>
    <link name="L_link5">
        <inertial>
            <origin rpy="0 0 0" xyz="-0.00023397 0.036705 -0.080064" />
            <mass value="0.18554" />
            <inertia ixx="0.00099549" ixy="8.9957E-07" ixz="8.5285E-07" iyy="0.0008853" iyz="-0.00025682" izz="0.00035048" />
        </inertial>
        <visual>
            <origin rpy="0 0 0" xyz="0 0 0" />
            <geometry>
                <mesh filename="package://xarm_description/meshes/xarm7/visual/link5.STL" />
            </geometry>
            <material name="L_White" />
        </visual>
        <collision>
            <origin rpy="0 0 0" xyz="0 0 0" />
            <geometry>
                <mesh filename="package://xarm_description/meshes/xarm7/visual/link5.STL" />
            </geometry>
        </collision>
    </link>
    <joint name="L_joint5" type="revolute">
        <origin rpy="1.5708 0 0" xyz="0.0775 -0.3425 0" />
        <parent link="L_link4" />
        <child link="L_link5" />
        <axis xyz="0 0 1" />
        <limit effort="30" lower="-6.283185307179586" upper="6.283185307179586" velocity="3.14" />
        <dynamics damping="5" friction="1" />
    </joint>
    <link name="L_link6">
        <inertial>
            <origin rpy="0 0 0" xyz="0.058911 0.028469 0.0068428" />
            <mass value="0.31344" />
            <inertia ixx="0.00052034" ixy="-0.00014989" ixz="0.00011658" iyy="0.00067968" iyz="6.116E-05" izz="0.00078345" />
        </inertial>
        <visual>
            <origin rpy="0 0 0" xyz="0 0 0" />
            <geometry>
                <mesh filename="package://xarm_description/meshes/xarm7/visual/link6.STL" />
            </geometry>
            <material name="L_White" />
        </visual>
        <collision>
            <origin rpy="0 0 0" xyz="0 0 0" />
            <geometry>
                <mesh filename="package://xarm_description/meshes/xarm7/visual/link6.STL" />
            </geometry>
        </collision>
    </link>
    <joint name="L_joint6" type="revolute">
        <origin rpy="1.5708 0 0" xyz="0 0 0" />
        <parent link="L_link5" />
        <child link="L_link6" />
        <axis xyz="0 0 1" />
        <limit effort="20" lower="-1.69297" upper="3.141592653589793" velocity="3.14" />
        <dynamics damping="2" friction="1" />
    </joint>
    <link name="L_link7">
        <inertial>
            <origin rpy="0 0 0" xyz="-1.5846E-05 -0.0046377 -0.012705" />
            <mass value="0.31468" />
            <inertia ixx="0.00016985" ixy="1.1102E-07" ixz="5.1075E-08" iyy="0.00011924" iyz="-2.1251E-06" izz="0.00026032" />
        </inertial>
        <visual>
            <origin rpy="0 0 0" xyz="0 0 0" />
            <geometry>
                <mesh filename="package://xarm_description/meshes/xarm7/visual/link7.STL" />
            </geometry>
            <material name="L_Silver" />
        </visual>
        <collision>
            <origin rpy="0 0 0" xyz="0 0 0" />
            <geometry>
                <mesh filename="package://xarm_description/meshes/collision/end_tool.STL" />
            </geometry>
        </collision>
    </link>
    <joint name="L_joint7" type="revolute">
        <origin rpy="-1.5708 0 0" xyz="0.076 0.097 0" />
        <parent link="L_link6" />
        <child link="L_link7" />
        <axis xyz="0 0 1" />
        <limit effort="20" lower="-6.283185307179586" upper="6.283185307179586" velocity="3.14" />
        <dynamics damping="2" friction="1" />
    </joint>
    <link name="L_link_eef" />
    <joint name="L_joint_eef" type="fixed">
        <origin rpy="0 0 0" xyz="0 0 0" />
        <parent link="L_link7" />
        <child link="L_link_eef" />
    </joint>
    <transmission name="L_tran1">
        <type>transmission_interface/SimpleTransmission</type>
        <joint name="L_joint1">
            <hardwareInterface>hardware_interface/PositionJointInterface</hardwareInterface>
        </joint>
        <actuator name="L_motor1">
            <hardwareInterface>hardware_interface/PositionJointInterface</hardwareInterface>
            <mechanicalReduction>100</mechanicalReduction>
        </actuator>
    </transmission>
    <transmission name="L_tran2">
        <type>transmission_interface/SimpleTransmission</type>
        <joint name="L_joint2">
            <hardwareInterface>hardware_interface/PositionJointInterface</hardwareInterface>
        </joint>
        <actuator name="L_motor2">
            <hardwareInterface>hardware_interface/PositionJointInterface</hardwareInterface>
            <mechanicalReduction>100</mechanicalReduction>
        </actuator>
    </transmission>
    <transmission name="L_tran3">
        <type>transmission_interface/SimpleTransmission</type>
        <joint name="L_joint3">
            <hardwareInterface>hardware_interface/PositionJointInterface</hardwareInterface>
        </joint>
        <actuator name="L_motor3">
            <hardwareInterface>hardware_interface/PositionJointInterface</hardwareInterface>
            <mechanicalReduction>100</mechanicalReduction>
        </actuator>
    </transmission>
    <transmission name="L_tran4">
        <type>transmission_interface/SimpleTransmission</type>
        <joint name="L_joint4">
            <hardwareInterface>hardware_interface/PositionJointInterface</hardwareInterface>
        </joint>
        <actuator name="L_motor3">
            <hardwareInterface>hardware_interface/PositionJointInterface</hardwareInterface>
            <mechanicalReduction>100</mechanicalReduction>
        </actuator>
    </transmission>
    <transmission name="L_tran5">
        <type>transmission_interface/SimpleTransmission</type>
        <joint name="L_joint5">
            <hardwareInterface>hardware_interface/PositionJointInterface</hardwareInterface>
        </joint>
        <actuator name="L_motor5">
            <hardwareInterface>hardware_interface/PositionJointInterface</hardwareInterface>
            <mechanicalReduction>100</mechanicalReduction>
        </actuator>
    </transmission>
    <transmission name="L_tran6">
        <type>transmission_interface/SimpleTransmission</type>
        <joint name="L_joint6">
            <hardwareInterface>hardware_interface/PositionJointInterface</hardwareInterface>
        </joint>
        <actuator name="L_motor6">
            <hardwareInterface>hardware_interface/PositionJointInterface</hardwareInterface>
            <mechanicalReduction>100</mechanicalReduction>
        </actuator>
    </transmission>
    <transmission name="L_tran7">
        <type>transmission_interface/SimpleTransmission</type>
        <joint name="L_joint7">
            <hardwareInterface>hardware_interface/PositionJointInterface</hardwareInterface>
        </joint>
        <actuator name="L_motor7">
            <hardwareInterface>hardware_interface/PositionJointInterface</hardwareInterface>
            <mechanicalReduction>100</mechanicalReduction>
        </actuator>
    </transmission>
    <gazebo reference="L_link_base">
        <selfCollide>true</selfCollide>
    </gazebo>
    <gazebo reference="L_link1">
        <selfCollide>true</selfCollide>
    </gazebo>
    <gazebo reference="L_link2">
        <selfCollide>true</selfCollide>
    </gazebo>
    <gazebo reference="L_link3">
        <selfCollide>true</selfCollide>
    </gazebo>
    <gazebo reference="L_link4">
        <selfCollide>true</selfCollide>
    </gazebo>
    <gazebo reference="L_link5">
        <selfCollide>true</selfCollide>
    </gazebo>
    <gazebo reference="L_link6">
        <selfCollide>true</selfCollide>
    </gazebo>
    <gazebo reference="L_link7">
        <selfCollide>true</selfCollide>
    </gazebo>
    <!-- gazebo plugin -->
    <!-- <xacro:gazebo_ros_control_plugin namespace="${ns}"/> -->
    <joint name="L_gripper_fix" type="fixed">
        <parent link="L_link_eef" />
        <child link="L_xarm_gripper_base_link" />
        <origin rpy="0 0 0" xyz="0 0 0" />
    </joint>
    <link name="L_xarm_gripper_base_link">
        <inertial>
            <origin rpy="0 0 0" xyz="-0.00065489 -0.0018497 0.048028" />
            <mass value="0.54156" />
            <inertia ixx="0.00047106" ixy="3.9292E-07" ixz="2.6537E-06" iyy="0.00033072" iyz="-1.0975E-05" izz="0.00025642" />
        </inertial>
        <visual>
            <origin rpy="0 0 0" xyz="0 0 0" />
            <geometry>
                <mesh filename="package://xarm_gripper/meshes/base_link.STL" />
            </geometry>
            <!-- <material
        name="">
        <color
          rgba="0.89804 0.91765 0.92941 1" />
      </material> -->
            <material name="White">
                <color rgba="1.0 1.0 1.0 1.0" />
            </material>
        </visual>
        <collision>
            <origin rpy="0 0 0" xyz="0 0 0" />
            <geometry>
                <mesh filename="package://xarm_gripper/meshes/base_link_collision.STL" />
            </geometry>
        </collision>
    </link>
    <link name="L_left_outer_knuckle">
        <inertial>
            <origin rpy="0 0 0" xyz="2.9948E-14 0.021559 0.015181" />
            <mass value="0.033618" />
            <inertia ixx="1.9111E-05" ixy="-1.8803E-17" ixz="-1.1002E-17" iyy="6.6256E-06" iyz="-7.3008E-06" izz="1.3185E-05" />
        </inertial>
        <visual>
            <origin rpy="0 0 0" xyz="0 0 0" />
            <geometry>
                <mesh filename="package://xarm_gripper/meshes/left_outer_knuckle.STL" />
            </geometry>
            <material name="Silver">
                <color rgba="0.753 0.753 0.753 1.0" />
            </material>
        </visual>
        <collision>
            <origin rpy="0 0 0" xyz="0 0 0" />
            <geometry>
                <mesh filename="package://xarm_gripper/meshes/left_outer_knuckle.STL" />
            </geometry>
        </collision>
    </link>
    <joint name="L_drive_joint" type="revolute">
        <origin rpy="0 0 0" xyz="0 0.035 0.059098" />
        <parent link="L_xarm_gripper_base_link" />
        <child link="L_left_outer_knuckle" />
        <axis xyz="1 0 0" />
        <limit effort="50" lower="0" upper="0.85" velocity="2" />
    </joint>
    <link name="L_left_finger">
        <inertial>
            <origin rpy="0 0 0" xyz="-2.4536E-14 -0.016413 0.029258" />
            <mass value="0.048304" />
            <inertia ixx="1.7493E-05" ixy="-4.2156E-19" ixz="6.9164E-18" iyy="1.7225E-05" iyz="4.6433E-06" izz="5.1466E-06" />
        </inertial>
        <visual>
            <origin rpy="0 0 0" xyz="0 0 0" />
            <geometry>
                <mesh filename="package://xarm_gripper/meshes/left_finger.STL" />
            </geometry>
            <material name="Silver">
                <color rgba="0.753 0.753 0.753 1.0" />
            </material>
        </visual>
        <collision>
            <origin rpy="0 0 0" xyz="0 0 0" />
            <geometry>
                <mesh filename="package://xarm_gripper/meshes/left_finger.STL" />
            </geometry>
        </collision>
    </link>
    <joint name="L_left_finger_joint" type="revolute">
        <origin rpy="0 0 0" xyz="0 0.035465 0.042039" />
        <parent link="L_left_outer_knuckle" />
        <child link="L_left_finger" />
        <axis xyz="-1 0 0" />
        <limit effort="50" lower="0" upper="0.85" velocity="2" />
        <mimic joint="L_drive_joint" multiplier="1" offset="0" />
    </joint>
    <link name="L_left_inner_knuckle">
        <inertial>
            <origin rpy="0 0 0" xyz="1.86600784687907E-06 0.0220467847633621 0.0261334672830885" />
            <mass value="0.0230125781256706" />
            <inertia ixx="6.09490024271906E-06" ixy="6.06651326160071E-11" ixz="7.19102670500635E-11" iyy="6.01955084375188E-06" iyz="-2.75316812991721E-06" izz="5.07862004479903E-06" />
        </inertial>
        <visual>
            <origin rpy="0 0 0" xyz="0 0 0" />
            <geometry>
                <mesh filename="package://xarm_gripper/meshes/left_inner_knuckle.STL" />
            </geometry>
            <material name="Silver">
                <color rgba="0.753 0.753 0.753 1.0" />
            </material>
        </visual>
        <collision>
            <origin rpy="0 0 0" xyz="0 0 0" />
            <geometry>
                <mesh filename="package://xarm_gripper/meshes/left_inner_knuckle.STL" />
            </geometry>
        </collision>
    </link>
    <joint name="L_left_inner_knuckle_joint" type="revolute">
        <origin rpy="0 0 0" xyz="0 0.02 0.074098" />
        <parent link="L_xarm_gripper_base_link" />
        <child link="L_left_inner_knuckle" />
        <axis xyz="1 0 0" />
        <limit effort="50" lower="0" upper="0.85" velocity="2" />
        <mimic joint="L_drive_joint" multiplier="1" offset="0" />
    </joint>
    <link name="L_right_outer_knuckle">
        <inertial>
            <origin rpy="0 0 0" xyz="-3.1669E-14 -0.021559 0.015181" />
            <mass value="0.033618" />
            <inertia ixx="1.9111E-05" ixy="-1.8789E-17" ixz="1.0986E-17" iyy="6.6256E-06" iyz="7.3008E-06" izz="1.3185E-05" />
        </inertial>
        <visual>
            <origin rpy="0 0 0" xyz="0 0 0" />
            <geometry>
                <mesh filename="package://xarm_gripper/meshes/right_outer_knuckle.STL" />
            </geometry>
            <material name="Silver">
                <color rgba="0.753 0.753 0.753 1.0" />
            </material>
        </visual>
        <collision>
            <origin rpy="0 0 0" xyz="0 0 0" />
            <geometry>
                <mesh filename="package://xarm_gripper/meshes/right_outer_knuckle.STL" />
            </geometry>
        </collision>
    </link>
    <joint name="L_right_outer_knuckle_joint" type="revolute">
        <origin rpy="0 0 0" xyz="0 -0.035 0.059098" />
        <parent link="L_xarm_gripper_base_link" />
        <child link="L_right_outer_knuckle" />
        <axis xyz="-1 0 0" />
        <limit effort="50" lower="0" upper="0.85" velocity="2" />
        <mimic joint="L_drive_joint" multiplier="1" offset="0" />
    </joint>
    <link name="L_right_finger">
        <inertial>
            <origin rpy="0 0 0" xyz="2.5618E-14 0.016413 0.029258" />
            <mass value="0.048304" />
            <inertia ixx="1.7493E-05" ixy="-5.0014E-19" ixz="-7.5079E-18" iyy="1.7225E-05" iyz="-4.6435E-06" izz="5.1466E-06" />
        </inertial>
        <visual>
            <origin rpy="0 0 0" xyz="0 0 0" />
            <geometry>
                <mesh filename="package://xarm_gripper/meshes/right_finger.STL" />
            </geometry>
            <material name="Silver">
                <color rgba="0.753 0.753 0.753 1.0" />
            </material>
        </visual>
        <collision>
            <origin rpy="0 0 0" xyz="0 0 0" />
            <geometry>
                <mesh filename="package://xarm_gripper/meshes/right_finger.STL" />
            </geometry>
        </collision>
    </link>
    <joint name="L_right_finger_joint" type="revolute">
        <origin rpy="0 0 0" xyz="0 -0.035465 0.042039" />
        <parent link="L_right_outer_knuckle" />
        <child link="L_right_finger" />
        <axis xyz="1 0 0" />
        <limit effort="50" lower="0" upper="0.85" velocity="2" />
        <mimic joint="L_drive_joint" multiplier="1" offset="0" />
    </joint>
    <link name="L_right_inner_knuckle">
        <inertial>
            <origin rpy="0 0 0" xyz="1.866E-06 -0.022047 0.026133" />
            <mass value="0.023013" />
            <inertia ixx="6.0949E-06" ixy="-6.0665E-11" ixz="7.191E-11" iyy="6.0197E-06" iyz="2.7531E-06" izz="5.0784E-06" />
        </inertial>
        <visual>
            <origin rpy="0 0 0" xyz="0 0 0" />
            <geometry>
                <mesh filename="package://xarm_gripper/meshes/right_inner_knuckle.STL" />
            </geometry>
            <material name="Silver">
                <color rgba="0.753 0.753 0.753 1.0" />
            </material>
        </visual>
        <collision>
            <origin rpy="0 0 0" xyz="0 0 0" />
            <geometry>
                <mesh filename="package://xarm_gripper/meshes/right_inner_knuckle.STL" />
            </geometry>
        </collision>
    </link>
    <joint name="L_right_inner_knuckle_joint" type="revolute">
        <origin rpy="0 0 0" xyz="0 -0.02 0.074098" />
        <parent link="L_xarm_gripper_base_link" />
        <child link="L_right_inner_knuckle" />
        <axis xyz="-1 0 0" />
        <limit effort="50" lower="0" upper="0.85" velocity="2" />
        <mimic joint="L_drive_joint" multiplier="1" offset="0" />
    </joint>
    <link name="L_link_tcp" />
    <joint name="L_joint_tcp" type="fixed">
        <origin rpy="0 0 0" xyz="0 0 0.172" />
        <parent link="L_xarm_gripper_base_link" />
        <child link="L_link_tcp" />
    </joint>
    <transmission name="L_drive_joint_trans">
        <type>transmission_interface/SimpleTransmission</type>
        <joint name="L_drive_joint">
            <hardwareInterface>hardware_interface/PositionJointInterface</hardwareInterface>
        </joint>
        <actuator name="L_drive_joint_motor">
            <hardwareInterface>hardware_interface/PositionJointInterface</hardwareInterface>
            <mechanicalReduction>1</mechanicalReduction>
        </actuator>
    </transmission>
    <gazebo reference="L_xarm_gripper_base_link">
        <selfCollide>false</selfCollide>
    </gazebo>
    <gazebo reference="L_left_outer_knuckle">
        <selfCollide>false</selfCollide>
    </gazebo>
    <gazebo reference="L_left_finger">
        <selfCollide>false</selfCollide>
    </gazebo>
    <gazebo reference="L_left_inner_knuckle">
        <selfCollide>false</selfCollide>
    </gazebo>
    <gazebo reference="L_right_outer_knuckle">
        <selfCollide>false</selfCollide>
    </gazebo>
    <gazebo reference="L_right_finger">
        <selfCollide>false</selfCollide>
    </gazebo>
    <gazebo reference="L_right_inner_knuckle">
        <selfCollide>false</selfCollide>
    </gazebo>
    <gazebo>
        <plugin filename="libgazebo_grasp_fix.so" name="gazebo_grasp_fix">
            <arm>
                <arm_name>xarm_gripper</arm_name>
                <palm_link>L_link7</palm_link>
                <gripper_link>L_left_inner_knuckle</gripper_link>
                <gripper_link>L_right_inner_knuckle</gripper_link>
                <!-- <gripper_link>${prefix}left_outer_knuckle</gripper_link>
          <gripper_link>${prefix}right_outer_knuckle</gripper_link> -->
                <gripper_link>L_left_finger</gripper_link>
                <gripper_link>L_right_finger</gripper_link>
            </arm>
            <forces_angle_tolerance>100</forces_angle_tolerance>
            <update_rate>10</update_rate>
            <grip_count_threshold>2</grip_count_threshold>
            <max_grip_count>3</max_grip_count>
            <release_tolerance>0.0198</release_tolerance>
            <disable_collisions_on_attach>false</disable_collisions_on_attach>
            <contact_topic>__default_topic__</contact_topic>
        </plugin>
    </gazebo>
    <gazebo>
        <!-- old version -->
        <plugin filename="libroboticsgroup_gazebo_mimic_joint_plugin.so" name="L_left_finger_jointmimic_joint_plugin">
            <!-- new version -->
            <!-- <plugin name="${name_prefix}mimic_joint_plugin" filename="libroboticsgroup_upatras_gazebo_mimic_joint_plugin.so"> -->
            <joint>L_drive_joint</joint>
            <mimicJoint>L_left_finger_joint</mimicJoint>
            <multiplier>1.0</multiplier>
            <offset>0</offset>
            <sensitiveness>0.0</sensitiveness>
            <!-- if absolute difference between setpoint and process value is below this threshold, do nothing; 0.0 = disable [rad] -->
            <maxEffort>10.0</maxEffort>
        </plugin>
    </gazebo>
    <gazebo>
        <!-- old version -->
        <plugin filename="libroboticsgroup_gazebo_mimic_joint_plugin.so" name="L_left_inner_knuckle_jointmimic_joint_plugin">
            <!-- new version -->
            <!-- <plugin name="${name_prefix}mimic_joint_plugin" filename="libroboticsgroup_upatras_gazebo_mimic_joint_plugin.so"> -->
            <joint>L_drive_joint</joint>
            <mimicJoint>L_left_inner_knuckle_joint</mimicJoint>
            <multiplier>1.0</multiplier>
            <offset>0</offset>
            <sensitiveness>0.0</sensitiveness>
            <!-- if absolute difference between setpoint and process value is below this threshold, do nothing; 0.0 = disable [rad] -->
            <maxEffort>10.0</maxEffort>
        </plugin>
    </gazebo>
    <gazebo>
        <!-- old version -->
        <plugin filename="libroboticsgroup_gazebo_mimic_joint_plugin.so" name="L_right_outer_knuckle_jointmimic_joint_plugin">
            <!-- new version -->
            <!-- <plugin name="${name_prefix}mimic_joint_plugin" filename="libroboticsgroup_upatras_gazebo_mimic_joint_plugin.so"> -->
            <joint>L_drive_joint</joint>
            <mimicJoint>L_right_outer_knuckle_joint</mimicJoint>
            <multiplier>1.0</multiplier>
            <offset>0</offset>
            <sensitiveness>0.0</sensitiveness>
            <!-- if absolute difference between setpoint and process value is below this threshold, do nothing; 0.0 = disable [rad] -->
            <maxEffort>10.0</maxEffort>
        </plugin>
    </gazebo>
    <gazebo>
        <!-- old version -->
        <plugin filename="libroboticsgroup_gazebo_mimic_joint_plugin.so" name="L_right_finger_jointmimic_joint_plugin">
            <!-- new version -->
            <!-- <plugin name="${name_prefix}mimic_joint_plugin" filename="libroboticsgroup_upatras_gazebo_mimic_joint_plugin.so"> -->
            <joint>L_drive_joint</joint>
            <mimicJoint>L_right_finger_joint</mimicJoint>
            <multiplier>1.0</multiplier>
            <offset>0</offset>
            <sensitiveness>0.0</sensitiveness>
            <!-- if absolute difference between setpoint and process value is below this threshold, do nothing; 0.0 = disable [rad] -->
            <maxEffort>10.0</maxEffort>
        </plugin>
    </gazebo>
    <gazebo>
        <!-- old version -->
        <plugin filename="libroboticsgroup_gazebo_mimic_joint_plugin.so" name="L_right_inner_knuckle_jointmimic_joint_plugin">
            <!-- new version -->
            <!-- <plugin name="${name_prefix}mimic_joint_plugin" filename="libroboticsgroup_upatras_gazebo_mimic_joint_plugin.so"> -->
            <joint>L_drive_joint</joint>
            <mimicJoint>L_right_inner_knuckle_joint</mimicJoint>
            <multiplier>1.0</multiplier>
            <offset>0</offset>
            <sensitiveness>0.0</sensitiveness>
            <!-- if absolute difference between setpoint and process value is below this threshold, do nothing; 0.0 = disable [rad] -->
            <maxEffort>10.0</maxEffort>
        </plugin>
    </gazebo>
    <!--
  Author: Jimy Zhang <jimy.zhang@ufactory.cc> <jimy92@163.com>
  Contributers:
-->
    <gazebo>
        <plugin filename="libgazebo_ros_control.so" name="gazebo_ros_control">
            <robotNamespace>/xarm</robotNamespace>
            <!-- <controlPeriod>0.0001</controlPeriod> -->
            <robotSimType>gazebo_ros_control/DefaultRobotHWSim</robotSimType>
            <legacyModeNS>true</legacyModeNS>
            <!-- <preserveWorldVelocity>true</preserveWorldVelocity> -->
        </plugin>
    </gazebo>
    <joint name="R_world_joint" type="fixed">
        <parent link="ground" />
        <child link="R_link_base" />
        <origin rpy="0 0 -0.523599" xyz="0 0.75 0.09" />
    </joint>
    <material name="R_Black">
        <color rgba="0.0 0.0 0.0 1.0" />
    </material>
    <material name="R_Red">
        <color rgba="0.8 0.0 0.0 1.0" />
    </material>
    <material name="R_White">
        <color rgba="1.0 1.0 1.0 1.0" />
    </material>
    <material name="R_Silver">
        <color rgba="0.753 0.753 0.753 1.0" />
    </material>
    <link name="R_link_base">
        <inertial>
            <origin rpy="0 0 0" xyz="-0.021131 -0.0016302 0.056488" />
            <mass value="0.88556" />
            <inertia ixx="0.0030595" ixy="0.00012259" ixz="-0.00062705" iyy="0.0037783" iyz="0.00027023" izz="0.0020125" />
        </inertial>
        <visual>
            <origin rpy="0 0 0" xyz="0 0 0" />
            <geometry>
                <mesh filename="package://xarm_description/meshes/xarm7/visual/link_base.STL" />
            </geometry>
            <material name="R_White" />
        </visual>
        <collision>
            <origin rpy="0 0 0" xyz="0 0 0" />
            <geometry>
                <mesh filename="package://xarm_description/meshes/xarm7/visual/link_base.STL" />
            </geometry>
        </collision>
    </link>
    <link name="R_link1">
        <inertial>
            <origin rpy="0 0 0" xyz="-0.0042142 0.02821 -0.0087788" />
            <mass value="0.42603" />
            <inertia ixx="0.0014243" ixy="3.9946E-05" ixz="4.7078E-06" iyy="0.00123" iyz="-0.00026073" izz="0.00099229" />
        </inertial>
        <visual>
            <origin rpy="0 0 0" xyz="0 0 0" />
            <geometry>
                <mesh filename="package://xarm_description/meshes/xarm7/visual/link1.STL" />
            </geometry>
            <material name="R_White" />
        </visual>
        <collision>
            <origin rpy="0 0 0" xyz="0 0 0" />
            <geometry>
                <mesh filename="package://xarm_description/meshes/xarm7/visual/link1.STL" />
            </geometry>
        </collision>
    </link>
    <joint name="R_joint1" type="revolute">
        <origin rpy="0 0 0" xyz="0 0 0.267" />
        <parent link="R_link_base" />
        <child link="R_link1" />
        <axis xyz="0 0 1" />
        <limit effort="50" lower="-6.283185307179586" upper="6.283185307179586" velocity="3.14" />
        <dynamics damping="10" friction="1" />
    </joint>
    <link name="R_link2">
        <inertial>
            <origin rpy="0 0 0" xyz="-3.3178E-05 -0.12849 0.026337" />
            <mass value="0.56095" />
            <inertia ixx="0.0031915" ixy="3.0892E-06" ixz="2.8729E-06" iyy="0.0017468" iyz="-0.0010241" izz="0.00235" />
        </inertial>
        <visual>
            <origin rpy="0 0 0" xyz="0 0 0" />
            <geometry>
                <mesh filename="package://xarm_description/meshes/xarm7/visual/link2.STL" />
            </geometry>
            <material name="R_White" />
        </visual>
        <collision>
            <origin rpy="0 0 0" xyz="0 0 0" />
            <geometry>
                <mesh filename="package://xarm_description/meshes/xarm7/visual/link2.STL" />
            </geometry>
        </collision>
    </link>
    <joint name="R_joint2" type="revolute">
        <origin rpy="-1.5708 0 0" xyz="0 0 0" />
        <parent link="R_link1" />
        <child link="R_link2" />
        <axis xyz="0 0 1" />
        <limit effort="50" lower="-2.059" upper="2.0944" velocity="3.14" />
        <dynamics damping="10" friction="1" />
    </joint>
    <link name="R_link3">
        <inertial>
            <origin rpy="0 0 0" xyz="0.04223 -0.023258 -0.0096674" />
            <mass value="0.44463" />
            <inertia ixx="0.0011454" ixy="0.0001654" ixz="-0.0001951" iyy="0.0010503" iyz="0.00012027" izz="0.0011083" />
        </inertial>
        <visual>
            <origin rpy="0 0 0" xyz="0 0 0" />
            <geometry>
                <mesh filename="package://xarm_description/meshes/xarm7/visual/link3.STL" />
            </geometry>
            <material name="R_White" />
        </visual>
        <collision>
            <origin rpy="0 0 0" xyz="0 0 0" />
            <geometry>
                <mesh filename="package://xarm_description/meshes/xarm7/visual/link3.STL" />
            </geometry>
        </collision>
    </link>
    <joint name="R_joint3" type="revolute">
        <origin rpy="1.5708 0 0" xyz="0 -0.293 0" />
        <parent link="R_link2" />
        <child link="R_link3" />
        <axis xyz="0 0 1" />
        <limit effort="30" lower="-6.283185307179586" upper="6.283185307179586" velocity="3.14" />
        <dynamics damping="5" friction="1" />
    </joint>
    <link name="R_link4">
        <inertial>
            <origin rpy="0 0 0" xyz="0.067148 -0.10732 0.024479" />
            <mass value="0.52387" />
            <inertia ixx="0.0026033" ixy="0.00053379" ixz="0.00036314" iyy="0.0017649" iyz="-0.00083253" izz="0.0022431" />
        </inertial>
        <visual>
            <origin rpy="0 0 0" xyz="0 0 0" />
            <geometry>
                <mesh filename="package://xarm_description/meshes/xarm7/visual/link4.STL" />
            </geometry>
            <material name="R_White" />
        </visual>
        <collision>
            <origin rpy="0 0 0" xyz="0 0 0" />
            <geometry>
                <mesh filename="package://xarm_description/meshes/xarm7/visual/link4.STL" />
            </geometry>
        </collision>
    </link>
    <joint name="R_joint4" type="revolute">
        <origin rpy="1.5708 0 0" xyz="0.0525 0 0" />
        <parent link="R_link3" />
        <child link="R_link4" />
        <axis xyz="0 0 1" />
        <limit effort="30" lower="-0.19198" upper="3.927" velocity="3.14" />
        <dynamics damping="5" friction="1" />
    </joint>
    <link name="R_link5">
        <inertial>
            <origin rpy="0 0 0" xyz="-0.00023397 0.036705 -0.080064" />
            <mass value="0.18554" />
            <inertia ixx="0.00099549" ixy="8.9957E-07" ixz="8.5285E-07" iyy="0.0008853" iyz="-0.00025682" izz="0.00035048" />
        </inertial>
        <visual>
            <origin rpy="0 0 0" xyz="0 0 0" />
            <geometry>
                <mesh filename="package://xarm_description/meshes/xarm7/visual/link5.STL" />
            </geometry>
            <material name="R_White" />
        </visual>
        <collision>
            <origin rpy="0 0 0" xyz="0 0 0" />
            <geometry>
                <mesh filename="package://xarm_description/meshes/xarm7/visual/link5.STL" />
            </geometry>
        </collision>
    </link>
    <joint name="R_joint5" type="revolute">
        <origin rpy="1.5708 0 0" xyz="0.0775 -0.3425 0" />
        <parent link="R_link4" />
        <child link="R_link5" />
        <axis xyz="0 0 1" />
        <limit effort="30" lower="-6.283185307179586" upper="6.283185307179586" velocity="3.14" />
        <dynamics damping="5" friction="1" />
    </joint>
    <link name="R_link6">
        <inertial>
            <origin rpy="0 0 0" xyz="0.058911 0.028469 0.0068428" />
            <mass value="0.31344" />
            <inertia ixx="0.00052034" ixy="-0.00014989" ixz="0.00011658" iyy="0.00067968" iyz="6.116E-05" izz="0.00078345" />
        </inertial>
        <visual>
            <origin rpy="0 0 0" xyz="0 0 0" />
            <geometry>
                <mesh filename="package://xarm_description/meshes/xarm7/visual/link6.STL" />
            </geometry>
            <material name="R_White" />
        </visual>
        <collision>
            <origin rpy="0 0 0" xyz="0 0 0" />
            <geometry>
                <mesh filename="package://xarm_description/meshes/xarm7/visual/link6.STL" />
            </geometry>
        </collision>
    </link>
    <joint name="R_joint6" type="revolute">
        <origin rpy="1.5708 0 0" xyz="0 0 0" />
        <parent link="R_link5" />
        <child link="R_link6" />
        <axis xyz="0 0 1" />
        <limit effort="20" lower="-1.69297" upper="3.141592653589793" velocity="3.14" />
        <dynamics damping="2" friction="1" />
    </joint>
    <link name="R_link7">
        <inertial>
            <origin rpy="0 0 0" xyz="-1.5846E-05 -0.0046377 -0.012705" />
            <mass value="0.31468" />
            <inertia ixx="0.00016985" ixy="1.1102E-07" ixz="5.1075E-08" iyy="0.00011924" iyz="-2.1251E-06" izz="0.00026032" />
        </inertial>
        <visual>
            <origin rpy="0 0 0" xyz="0 0 0" />
            <geometry>
                <mesh filename="package://xarm_description/meshes/xarm7/visual/link7.STL" />
            </geometry>
            <material name="R_Silver" />
        </visual>
        <collision>
            <origin rpy="0 0 0" xyz="0 0 0" />
            <geometry>
                <mesh filename="package://xarm_description/meshes/collision/end_tool.STL" />
            </geometry>
        </collision>
    </link>
    <joint name="R_joint7" type="revolute">
        <origin rpy="-1.5708 0 0" xyz="0.076 0.097 0" />
        <parent link="R_link6" />
        <child link="R_link7" />
        <axis xyz="0 0 1" />
        <limit effort="20" lower="-6.283185307179586" upper="6.283185307179586" velocity="3.14" />
        <dynamics damping="2" friction="1" />
    </joint>
    <link name="R_link_eef" />
    <joint name="R_joint_eef" type="fixed">
        <origin rpy="0 0 0" xyz="0 0 0" />
        <parent link="R_link7" />
        <child link="R_link_eef" />
    </joint>
    <transmission name="R_tran1">
        <type>transmission_interface/SimpleTransmission</type>
        <joint name="R_joint1">
            <hardwareInterface>hardware_interface/PositionJointInterface</hardwareInterface>
        </joint>
        <actuator name="R_motor1">
            <hardwareInterface>hardware_interface/PositionJointInterface</hardwareInterface>
            <mechanicalReduction>100</mechanicalReduction>
        </actuator>
    </transmission>
    <transmission name="R_tran2">
        <type>transmission_interface/SimpleTransmission</type>
        <joint name="R_joint2">
            <hardwareInterface>hardware_interface/PositionJointInterface</hardwareInterface>
        </joint>
        <actuator name="R_motor2">
            <hardwareInterface>hardware_interface/PositionJointInterface</hardwareInterface>
            <mechanicalReduction>100</mechanicalReduction>
        </actuator>
    </transmission>
    <transmission name="R_tran3">
        <type>transmission_interface/SimpleTransmission</type>
        <joint name="R_joint3">
            <hardwareInterface>hardware_interface/PositionJointInterface</hardwareInterface>
        </joint>
        <actuator name="R_motor3">
            <hardwareInterface>hardware_interface/PositionJointInterface</hardwareInterface>
            <mechanicalReduction>100</mechanicalReduction>
        </actuator>
    </transmission>
    <transmission name="R_tran4">
        <type>transmission_interface/SimpleTransmission</type>
        <joint name="R_joint4">
            <hardwareInterface>hardware_interface/PositionJointInterface</hardwareInterface>
        </joint>
        <actuator name="R_motor3">
            <hardwareInterface>hardware_interface/PositionJointInterface</hardwareInterface>
            <mechanicalReduction>100</mechanicalReduction>
        </actuator>
    </transmission>
    <transmission name="R_tran5">
        <type>transmission_interface/SimpleTransmission</type>
        <joint name="R_joint5">
            <hardwareInterface>hardware_interface/PositionJointInterface</hardwareInterface>
        </joint>
        <actuator name="R_motor5">
            <hardwareInterface>hardware_interface/PositionJointInterface</hardwareInterface>
            <mechanicalReduction>100</mechanicalReduction>
        </actuator>
    </transmission>
    <transmission name="R_tran6">
        <type>transmission_interface/SimpleTransmission</type>
        <joint name="R_joint6">
            <hardwareInterface>hardware_interface/PositionJointInterface</hardwareInterface>
        </joint>
        <actuator name="R_motor6">
            <hardwareInterface>hardware_interface/PositionJointInterface</hardwareInterface>
            <mechanicalReduction>100</mechanicalReduction>
        </actuator>
    </transmission>
    <transmission name="R_tran7">
        <type>transmission_interface/SimpleTransmission</type>
        <joint name="R_joint7">
            <hardwareInterface>hardware_interface/PositionJointInterface</hardwareInterface>
        </joint>
        <actuator name="R_motor7">
            <hardwareInterface>hardware_interface/PositionJointInterface</hardwareInterface>
            <mechanicalReduction>100</mechanicalReduction>
        </actuator>
    </transmission>
    <gazebo reference="R_link_base">
        <selfCollide>true</selfCollide>
    </gazebo>
    <gazebo reference="R_link1">
        <selfCollide>true</selfCollide>
    </gazebo>
    <gazebo reference="R_link2">
        <selfCollide>true</selfCollide>
    </gazebo>
    <gazebo reference="R_link3">
        <selfCollide>true</selfCollide>
    </gazebo>
    <gazebo reference="R_link4">
        <selfCollide>true</selfCollide>
    </gazebo>
    <gazebo reference="R_link5">
        <selfCollide>true</selfCollide>
    </gazebo>
    <gazebo reference="R_link6">
        <selfCollide>true</selfCollide>
    </gazebo>
    <gazebo reference="R_link7">
        <selfCollide>true</selfCollide>
    </gazebo>
    <!-- gazebo plugin -->
    <!-- <xacro:gazebo_ros_control_plugin namespace="${ns}"/> -->
    <joint name="R_gripper_fix" type="fixed">
        <parent link="R_link_eef" />
        <child link="R_xarm_gripper_base_link" />
        <origin rpy="0 0 0" xyz="0 0 0" />
    </joint>
    <link name="R_xarm_gripper_base_link">
        <inertial>
            <origin rpy="0 0 0" xyz="-0.00065489 -0.0018497 0.048028" />
            <mass value="0.54156" />
            <inertia ixx="0.00047106" ixy="3.9292E-07" ixz="2.6537E-06" iyy="0.00033072" iyz="-1.0975E-05" izz="0.00025642" />
        </inertial>
        <visual>
            <origin rpy="0 0 0" xyz="0 0 0" />
            <geometry>
                <mesh filename="package://xarm_gripper/meshes/base_link.STL" />
            </geometry>
            <!-- <material
        name="">
        <color
          rgba="0.89804 0.91765 0.92941 1" />
      </material> -->
            <material name="White">
                <color rgba="1.0 1.0 1.0 1.0" />
            </material>
        </visual>
        <collision>
            <origin rpy="0 0 0" xyz="0 0 0" />
            <geometry>
                <mesh filename="package://xarm_gripper/meshes/base_link_collision.STL" />
            </geometry>
        </collision>
    </link>
    <link name="R_left_outer_knuckle">
        <inertial>
            <origin rpy="0 0 0" xyz="2.9948E-14 0.021559 0.015181" />
            <mass value="0.033618" />
            <inertia ixx="1.9111E-05" ixy="-1.8803E-17" ixz="-1.1002E-17" iyy="6.6256E-06" iyz="-7.3008E-06" izz="1.3185E-05" />
        </inertial>
        <visual>
            <origin rpy="0 0 0" xyz="0 0 0" />
            <geometry>
                <mesh filename="package://xarm_gripper/meshes/left_outer_knuckle.STL" />
            </geometry>
            <material name="Silver">
                <color rgba="0.753 0.753 0.753 1.0" />
            </material>
        </visual>
        <collision>
            <origin rpy="0 0 0" xyz="0 0 0" />
            <geometry>
                <mesh filename="package://xarm_gripper/meshes/left_outer_knuckle.STL" />
            </geometry>
        </collision>
    </link>
    <joint name="R_drive_joint" type="revolute">
        <origin rpy="0 0 0" xyz="0 0.035 0.059098" />
        <parent link="R_xarm_gripper_base_link" />
        <child link="R_left_outer_knuckle" />
        <axis xyz="1 0 0" />
        <limit effort="50" lower="0" upper="0.85" velocity="2" />
    </joint>
    <link name="R_left_finger">
        <inertial>
            <origin rpy="0 0 0" xyz="-2.4536E-14 -0.016413 0.029258" />
            <mass value="0.048304" />
            <inertia ixx="1.7493E-05" ixy="-4.2156E-19" ixz="6.9164E-18" iyy="1.7225E-05" iyz="4.6433E-06" izz="5.1466E-06" />
        </inertial>
        <visual>
            <origin rpy="0 0 0" xyz="0 0 0" />
            <geometry>
                <mesh filename="package://xarm_gripper/meshes/left_finger.STL" />
            </geometry>
            <material name="Silver">
                <color rgba="0.753 0.753 0.753 1.0" />
            </material>
        </visual>
        <collision>
            <origin rpy="0 0 0" xyz="0 0 0" />
            <geometry>
                <mesh filename="package://xarm_gripper/meshes/left_finger.STL" />
            </geometry>
        </collision>
    </link>
    <joint name="R_left_finger_joint" type="revolute">
        <origin rpy="0 0 0" xyz="0 0.035465 0.042039" />
        <parent link="R_left_outer_knuckle" />
        <child link="R_left_finger" />
        <axis xyz="-1 0 0" />
        <limit effort="50" lower="0" upper="0.85" velocity="2" />
        <mimic joint="R_drive_joint" multiplier="1" offset="0" />
    </joint>
    <link name="R_left_inner_knuckle">
        <inertial>
            <origin rpy="0 0 0" xyz="1.86600784687907E-06 0.0220467847633621 0.0261334672830885" />
            <mass value="0.0230125781256706" />
            <inertia ixx="6.09490024271906E-06" ixy="6.06651326160071E-11" ixz="7.19102670500635E-11" iyy="6.01955084375188E-06" iyz="-2.75316812991721E-06" izz="5.07862004479903E-06" />
        </inertial>
        <visual>
            <origin rpy="0 0 0" xyz="0 0 0" />
            <geometry>
                <mesh filename="package://xarm_gripper/meshes/left_inner_knuckle.STL" />
            </geometry>
            <material name="Silver">
                <color rgba="0.753 0.753 0.753 1.0" />
            </material>
        </visual>
        <collision>
            <origin rpy="0 0 0" xyz="0 0 0" />
            <geometry>
                <mesh filename="package://xarm_gripper/meshes/left_inner_knuckle.STL" />
            </geometry>
        </collision>
    </link>
    <joint name="R_left_inner_knuckle_joint" type="revolute">
        <origin rpy="0 0 0" xyz="0 0.02 0.074098" />
        <parent link="R_xarm_gripper_base_link" />
        <child link="R_left_inner_knuckle" />
        <axis xyz="1 0 0" />
        <limit effort="50" lower="0" upper="0.85" velocity="2" />
        <mimic joint="R_drive_joint" multiplier="1" offset="0" />
    </joint>
    <link name="R_right_outer_knuckle">
        <inertial>
            <origin rpy="0 0 0" xyz="-3.1669E-14 -0.021559 0.015181" />
            <mass value="0.033618" />
            <inertia ixx="1.9111E-05" ixy="-1.8789E-17" ixz="1.0986E-17" iyy="6.6256E-06" iyz="7.3008E-06" izz="1.3185E-05" />
        </inertial>
        <visual>
            <origin rpy="0 0 0" xyz="0 0 0" />
            <geometry>
                <mesh filename="package://xarm_gripper/meshes/right_outer_knuckle.STL" />
            </geometry>
            <material name="Silver">
                <color rgba="0.753 0.753 0.753 1.0" />
            </material>
        </visual>
        <collision>
            <origin rpy="0 0 0" xyz="0 0 0" />
            <geometry>
                <mesh filename="package://xarm_gripper/meshes/right_outer_knuckle.STL" />
            </geometry>
        </collision>
    </link>
    <joint name="R_right_outer_knuckle_joint" type="revolute">
        <origin rpy="0 0 0" xyz="0 -0.035 0.059098" />
        <parent link="R_xarm_gripper_base_link" />
        <child link="R_right_outer_knuckle" />
        <axis xyz="-1 0 0" />
        <limit effort="50" lower="0" upper="0.85" velocity="2" />
        <mimic joint="R_drive_joint" multiplier="1" offset="0" />
    </joint>
    <link name="R_right_finger">
        <inertial>
            <origin rpy="0 0 0" xyz="2.5618E-14 0.016413 0.029258" />
            <mass value="0.048304" />
            <inertia ixx="1.7493E-05" ixy="-5.0014E-19" ixz="-7.5079E-18" iyy="1.7225E-05" iyz="-4.6435E-06" izz="5.1466E-06" />
        </inertial>
        <visual>
            <origin rpy="0 0 0" xyz="0 0 0" />
            <geometry>
                <mesh filename="package://xarm_gripper/meshes/right_finger.STL" />
            </geometry>
            <material name="Silver">
                <color rgba="0.753 0.753 0.753 1.0" />
            </material>
        </visual>
        <collision>
            <origin rpy="0 0 0" xyz="0 0 0" />
            <geometry>
                <mesh filename="package://xarm_gripper/meshes/right_finger.STL" />
            </geometry>
        </collision>
    </link>
    <joint name="R_right_finger_joint" type="revolute">
        <origin rpy="0 0 0" xyz="0 -0.035465 0.042039" />
        <parent link="R_right_outer_knuckle" />
        <child link="R_right_finger" />
        <axis xyz="1 0 0" />
        <limit effort="50" lower="0" upper="0.85" velocity="2" />
        <mimic joint="R_drive_joint" multiplier="1" offset="0" />
    </joint>
    <link name="R_right_inner_knuckle">
        <inertial>
            <origin rpy="0 0 0" xyz="1.866E-06 -0.022047 0.026133" />
            <mass value="0.023013" />
            <inertia ixx="6.0949E-06" ixy="-6.0665E-11" ixz="7.191E-11" iyy="6.0197E-06" iyz="2.7531E-06" izz="5.0784E-06" />
        </inertial>
        <visual>
            <origin rpy="0 0 0" xyz="0 0 0" />
            <geometry>
                <mesh filename="package://xarm_gripper/meshes/right_inner_knuckle.STL" />
            </geometry>
            <material name="Silver">
                <color rgba="0.753 0.753 0.753 1.0" />
            </material>
        </visual>
        <collision>
            <origin rpy="0 0 0" xyz="0 0 0" />
            <geometry>
                <mesh filename="package://xarm_gripper/meshes/right_inner_knuckle.STL" />
            </geometry>
        </collision>
    </link>
    <joint name="R_right_inner_knuckle_joint" type="revolute">
        <origin rpy="0 0 0" xyz="0 -0.02 0.074098" />
        <parent link="R_xarm_gripper_base_link" />
        <child link="R_right_inner_knuckle" />
        <axis xyz="-1 0 0" />
        <limit effort="50" lower="0" upper="0.85" velocity="2" />
        <mimic joint="R_drive_joint" multiplier="1" offset="0" />
    </joint>
    <link name="R_link_tcp" />
    <joint name="R_joint_tcp" type="fixed">
        <origin rpy="0 0 0" xyz="0 0 0.172" />
        <parent link="R_xarm_gripper_base_link" />
        <child link="R_link_tcp" />
    </joint>
    <transmission name="R_drive_joint_trans">
        <type>transmission_interface/SimpleTransmission</type>
        <joint name="R_drive_joint">
            <hardwareInterface>hardware_interface/PositionJointInterface</hardwareInterface>
        </joint>
        <actuator name="R_drive_joint_motor">
            <hardwareInterface>hardware_interface/PositionJointInterface</hardwareInterface>
            <mechanicalReduction>1</mechanicalReduction>
        </actuator>
    </transmission>
    <gazebo reference="R_xarm_gripper_base_link">
        <selfCollide>false</selfCollide>
    </gazebo>
    <gazebo reference="R_left_outer_knuckle">
        <selfCollide>false</selfCollide>
    </gazebo>
    <gazebo reference="R_left_finger">
        <selfCollide>false</selfCollide>
    </gazebo>
    <gazebo reference="R_left_inner_knuckle">
        <selfCollide>false</selfCollide>
    </gazebo>
    <gazebo reference="R_right_outer_knuckle">
        <selfCollide>false</selfCollide>
    </gazebo>
    <gazebo reference="R_right_finger">
        <selfCollide>false</selfCollide>
    </gazebo>
    <gazebo reference="R_right_inner_knuckle">
        <selfCollide>false</selfCollide>
    </gazebo>
    <gazebo>
        <plugin filename="libgazebo_grasp_fix.so" name="gazebo_grasp_fix">
            <arm>
                <arm_name>xarm_gripper</arm_name>
                <palm_link>R_link7</palm_link>
                <gripper_link>R_left_inner_knuckle</gripper_link>
                <gripper_link>R_right_inner_knuckle</gripper_link>
                <!-- <gripper_link>${prefix}left_outer_knuckle</gripper_link>
          <gripper_link>${prefix}right_outer_knuckle</gripper_link> -->
                <gripper_link>R_left_finger</gripper_link>
                <gripper_link>R_right_finger</gripper_link>
            </arm>
            <forces_angle_tolerance>100</forces_angle_tolerance>
            <update_rate>10</update_rate>
            <grip_count_threshold>2</grip_count_threshold>
            <max_grip_count>3</max_grip_count>
            <release_tolerance>0.0198</release_tolerance>
            <disable_collisions_on_attach>false</disable_collisions_on_attach>
            <contact_topic>__default_topic__</contact_topic>
        </plugin>
    </gazebo>
    <gazebo>
        <!-- old version -->
        <plugin filename="libroboticsgroup_gazebo_mimic_joint_plugin.so" name="R_left_finger_jointmimic_joint_plugin">
            <!-- new version -->
            <!-- <plugin name="${name_prefix}mimic_joint_plugin" filename="libroboticsgroup_upatras_gazebo_mimic_joint_plugin.so"> -->
            <joint>R_drive_joint</joint>
            <mimicJoint>R_left_finger_joint</mimicJoint>
            <multiplier>1.0</multiplier>
            <offset>0</offset>
            <sensitiveness>0.0</sensitiveness>
            <!-- if absolute difference between setpoint and process value is below this threshold, do nothing; 0.0 = disable [rad] -->
            <maxEffort>10.0</maxEffort>
        </plugin>
    </gazebo>
    <gazebo>
        <!-- old version -->
        <plugin filename="libroboticsgroup_gazebo_mimic_joint_plugin.so" name="R_left_inner_knuckle_jointmimic_joint_plugin">
            <!-- new version -->
            <!-- <plugin name="${name_prefix}mimic_joint_plugin" filename="libroboticsgroup_upatras_gazebo_mimic_joint_plugin.so"> -->
            <joint>R_drive_joint</joint>
            <mimicJoint>R_left_inner_knuckle_joint</mimicJoint>
            <multiplier>1.0</multiplier>
            <offset>0</offset>
            <sensitiveness>0.0</sensitiveness>
            <!-- if absolute difference between setpoint and process value is below this threshold, do nothing; 0.0 = disable [rad] -->
            <maxEffort>10.0</maxEffort>
        </plugin>
    </gazebo>
    <gazebo>
        <!-- old version -->
        <plugin filename="libroboticsgroup_gazebo_mimic_joint_plugin.so" name="R_right_outer_knuckle_jointmimic_joint_plugin">
            <!-- new version -->
            <!-- <plugin name="${name_prefix}mimic_joint_plugin" filename="libroboticsgroup_upatras_gazebo_mimic_joint_plugin.so"> -->
            <joint>R_drive_joint</joint>
            <mimicJoint>R_right_outer_knuckle_joint</mimicJoint>
            <multiplier>1.0</multiplier>
            <offset>0</offset>
            <sensitiveness>0.0</sensitiveness>
            <!-- if absolute difference between setpoint and process value is below this threshold, do nothing; 0.0 = disable [rad] -->
            <maxEffort>10.0</maxEffort>
        </plugin>
    </gazebo>
    <gazebo>
        <!-- old version -->
        <plugin filename="libroboticsgroup_gazebo_mimic_joint_plugin.so" name="R_right_finger_jointmimic_joint_plugin">
            <!-- new version -->
            <!-- <plugin name="${name_prefix}mimic_joint_plugin" filename="libroboticsgroup_upatras_gazebo_mimic_joint_plugin.so"> -->
            <joint>R_drive_joint</joint>
            <mimicJoint>R_right_finger_joint</mimicJoint>
            <multiplier>1.0</multiplier>
            <offset>0</offset>
            <sensitiveness>0.0</sensitiveness>
            <!-- if absolute difference between setpoint and process value is below this threshold, do nothing; 0.0 = disable [rad] -->
            <maxEffort>10.0</maxEffort>
        </plugin>
    </gazebo>
    <gazebo>
        <!-- old version -->
        <plugin filename="libroboticsgroup_gazebo_mimic_joint_plugin.so" name="R_right_inner_knuckle_jointmimic_joint_plugin">
            <!-- new version -->
            <!-- <plugin name="${name_prefix}mimic_joint_plugin" filename="libroboticsgroup_upatras_gazebo_mimic_joint_plugin.so"> -->
            <joint>R_drive_joint</joint>
            <mimicJoint>R_right_inner_knuckle_joint</mimicJoint>
            <multiplier>1.0</multiplier>
            <offset>0</offset>
            <sensitiveness>0.0</sensitiveness>
            <!-- if absolute difference between setpoint and process value is below this threshold, do nothing; 0.0 = disable [rad] -->
            <maxEffort>10.0</maxEffort>
        </plugin>
    </gazebo>
    <transmission name="trans_L_left_finger_joint">
        <type>transmission_interface/SimpleTransmission</type>
        <joint name="L_left_finger_joint">
            <hardwareInterface>hardware_interface/EffortJointInterface</hardwareInterface>
        </joint>
        <actuator name="L_left_finger_joint_motor">
            <hardwareInterface>hardware_interface/EffortJointInterface</hardwareInterface>
            <mechanicalReduction>1</mechanicalReduction>
        </actuator>
    </transmission>
    <transmission name="trans_L_left_inner_knuckle_joint">
        <type>transmission_interface/SimpleTransmission</type>
        <joint name="L_left_inner_knuckle_joint">
            <hardwareInterface>hardware_interface/EffortJointInterface</hardwareInterface>
        </joint>
        <actuator name="L_left_inner_knuckle_joint_motor">
            <hardwareInterface>hardware_interface/EffortJointInterface</hardwareInterface>
            <mechanicalReduction>1</mechanicalReduction>
        </actuator>
    </transmission>
    <transmission name="trans_L_right_outer_knuckle_joint">
        <type>transmission_interface/SimpleTransmission</type>
        <joint name="L_right_outer_knuckle_joint">
            <hardwareInterface>hardware_interface/EffortJointInterface</hardwareInterface>
        </joint>
        <actuator name="L_right_outer_knuckle_joint_motor">
            <hardwareInterface>hardware_interface/EffortJointInterface</hardwareInterface>
            <mechanicalReduction>1</mechanicalReduction>
        </actuator>
    </transmission>
    <transmission name="trans_L_right_finger_joint">
        <type>transmission_interface/SimpleTransmission</type>
        <joint name="L_right_finger_joint">
            <hardwareInterface>hardware_interface/EffortJointInterface</hardwareInterface>
        </joint>
        <actuator name="L_right_finger_joint_motor">
            <hardwareInterface>hardware_interface/EffortJointInterface</hardwareInterface>
            <mechanicalReduction>1</mechanicalReduction>
        </actuator>
    </transmission>
    <transmission name="trans_L_right_inner_knuckle_joint">
        <type>transmission_interface/SimpleTransmission</type>
        <joint name="L_right_inner_knuckle_joint">
            <hardwareInterface>hardware_interface/EffortJointInterface</hardwareInterface>
        </joint>
        <actuator name="L_right_inner_knuckle_joint_motor">
            <hardwareInterface>hardware_interface/EffortJointInterface</hardwareInterface>
            <mechanicalReduction>1</mechanicalReduction>
        </actuator>
    </transmission>
    <transmission name="trans_R_left_finger_joint">
        <type>transmission_interface/SimpleTransmission</type>
        <joint name="R_left_finger_joint">
            <hardwareInterface>hardware_interface/EffortJointInterface</hardwareInterface>
        </joint>
        <actuator name="R_left_finger_joint_motor">
            <hardwareInterface>hardware_interface/EffortJointInterface</hardwareInterface>
            <mechanicalReduction>1</mechanicalReduction>
        </actuator>
    </transmission>
    <transmission name="trans_R_left_inner_knuckle_joint">
        <type>transmission_interface/SimpleTransmission</type>
        <joint name="R_left_inner_knuckle_joint">
            <hardwareInterface>hardware_interface/EffortJointInterface</hardwareInterface>
        </joint>
        <actuator name="R_left_inner_knuckle_joint_motor">
            <hardwareInterface>hardware_interface/EffortJointInterface</hardwareInterface>
            <mechanicalReduction>1</mechanicalReduction>
        </actuator>
    </transmission>
    <transmission name="trans_R_right_outer_knuckle_joint">
        <type>transmission_interface/SimpleTransmission</type>
        <joint name="R_right_outer_knuckle_joint">
            <hardwareInterface>hardware_interface/EffortJointInterface</hardwareInterface>
        </joint>
        <actuator name="R_right_outer_knuckle_joint_motor">
            <hardwareInterface>hardware_interface/EffortJointInterface</hardwareInterface>
            <mechanicalReduction>1</mechanicalReduction>
        </actuator>
    </transmission>
    <transmission name="trans_R_right_finger_joint">
        <type>transmission_interface/SimpleTransmission</type>
        <joint name="R_right_finger_joint">
            <hardwareInterface>hardware_interface/EffortJointInterface</hardwareInterface>
        </joint>
        <actuator name="R_right_finger_joint_motor">
            <hardwareInterface>hardware_interface/EffortJointInterface</hardwareInterface>
            <mechanicalReduction>1</mechanicalReduction>
        </actuator>
    </transmission>
    <transmission name="trans_R_right_inner_knuckle_joint">
        <type>transmission_interface/SimpleTransmission</type>
        <joint name="R_right_inner_knuckle_joint">
            <hardwareInterface>hardware_interface/EffortJointInterface</hardwareInterface>
        </joint>
        <actuator name="R_right_inner_knuckle_joint_motor">
            <hardwareInterface>hardware_interface/EffortJointInterface</hardwareInterface>
            <mechanicalReduction>1</mechanicalReduction>
        </actuator>
    </transmission>
</robot>

